Workbook

Sheet Данные
A1: Задача 2.16. Кривая Филлипса: данные
A2: Синий шрифт — исходные данные из условия, их можно менять; чёрный — формулы; зелёный — ссылки на другие листы.
A3: Модель: δw = β₁ + β₂·(1/u) + ε, где δw — темп роста зарплаты в процентах, u — уровень безработицы в процентах.
A5: t | B5: w — зарплата | C5: u — безработица, % | D5: δw = 100·(wₜ − wₜ₋₁)/wₜ₋₁ | E5: z = 1/u
A6: 1 | B6: 1.62 | C6: 1 | D6: — | E6: —
A7: 2 | B7: 1.65 | C7: 1.4 | D7: =100*(B7-B6)/B6 | E7: =1/C7
A8: 3 | B8: 1.79 | C8: 1.1 | D8: =100*(B8-B7)/B7 | E8: =1/C8
A9: 4 | B9: 1.94 | C9: 1.5 | D9: =100*(B9-B8)/B8 | E9: =1/C9
A10: 5 | B10: 2.03 | C10: 1.5 | D10: =100*(B10-B9)/B9 | E10: =1/C10
A11: 6 | B11: 2.12 | C11: 1.2 | D11: =100*(B11-B10)/B10 | E11: =1/C11
A12: 7 | B12: 2.26 | C12: 1 | D12: =100*(B12-B11)/B11 | E12: =1/C12
A13: 8 | B13: 2.44 | C13: 1.1 | D13: =100*(B13-B12)/B12 | E13: =1/C13
A14: 9 | B14: 2.57 | C14: 1.3 | D14: =100*(B14-B13)/B13 | E14: =1/C14
A15: 10 | B15: 2.66 | C15: 1.8 | D15: =100*(B15-B14)/B14 | E15: =1/C15
A16: 11 | B16: 2.73 | C16: 1.9 | D16: =100*(B16-B15)/B15 | E16: =1/C16
A17: 12 | B17: 2.8 | C17: 1.5 | D17: =100*(B17-B16)/B16 | E17: =1/C17
A18: 13 | B18: 2.92 | C18: 1.4 | D18: =100*(B18-B17)/B17 | E18: =1/C18
... A23: 18 | B23: 3.58 | C23: 1.4 | D23: =100*(B23-B22)/B22 | E23: =1/C23
A25: Источник данных: условие задачи 2.16, «Сборник задач к начальному курсу эконометрики» (РАНХиГС).
A26: В регрессии участвуют строки t = 2…18: для t = 1 темп роста не определён.

Sheet а) Оценки
A1: а) Оценки коэффициентов и проверка значимости
A2: Регрессия δw на z = 1/u со свободным членом по наблюдениям t = 2…18.
A4: Шаг 1. Средние и суммы в отклонениях
A5: n — число наблюдений | B5: =COUNT(Данные!$D$7:$D$23) | C5: =СЧЁТ(столбец δw)
A6: z̄ — среднее 1/u | B6: =AVERAGE(Данные!$E$7:$E$23) | C6: =СРЗНАЧ(столбец z)
A7: δw̄ — среднее δw | B7: =AVERAGE(Данные!$D$7:$D$23) | C7: =СРЗНАЧ(столбец δw)
A8: Σ(z − z̄)² | B8: =DEVSQ(Данные!$E$7:$E$23) | C8: =КВАДРОТКЛ(столбец z)
A9: Σ(z − z̄)(δw − δw̄) | B9: =SUMPRODUCT(Данные!$E$7:$E$23-B6,Данные!$D$7:$D$23-B7) | C9: =СУММПРОИЗВ(z − z̄; δw − δw̄)
A10: TSS = Σ(δw − δw̄)² | B10: =DEVSQ(Данные!$D$7:$D$23) | C10: =КВАДРОТКЛ(столбец δw)
A12: Шаг 2. Оценки МНК
A13: β̂₂ — коэффициент при 1/u | B13: =B9/B8 | C13: β̂₂ = Σ(z − z̄)(δw − δw̄) / Σ(z − z̄)²
A14: β̂₁ — свободный член | B14: =B7-B13*B6 | C14: β̂₁ = δw̄ − β̂₂·z̄
A16: Шаг 3. Подогнанные значения и остатки
A17: t | B17: δw | C17: z = 1/u | D17: δŵ = β̂₁ + β̂₂·z | E17: e = δw − δŵ | F17: e²
A18: =Данные!A7 | B18: =Данные!D7 | C18: =Данные!E7 | D18: =$B$14+$B$13*C18 | E18: =B18-D18 | F18: =E18^2
A19: =Данные!A8 | B19: =Данные!D8 | C19: =Данные!E8 | D19: =$B$14+$B$13*C19 | E19: =B19-D19 | F19: =E19^2
A20: =Данные!A9 | B20: =Данные!D9 | C20: =Данные!E9 | D20: =$B$14+$B$13*C20 | E20: =B20-D20 | F20: =E20^2
A21: =Данные!A10 | B21: =Данные!D10 | C21: =Данные!E10 | D21: =$B$14+$B$13*C21 | E21: =B21-D21 | F21: =E21^2
A22: =Данные!A11 | B22: =Данные!D11 | C22: =Данные!E11 | D22: =$B$14+$B$13*C22 | E22: =B22-D22 | F22: =E22^2
A23: =Данные!A12 | B23: =Данные!D12 | C23: =Данные!E12 | D23: =$B$14+$B$13*C23 | E23: =B23-D23 | F23: =E23^2
A24: =Данные!A13 | B24: =Данные!D13 | C24: =Данные!E13 | D24: =$B$14+$B$13*C24 | E24: =B24-D24 | F24: =E24^2
A25: =Данные!A14 | B25: =Данные!D14 | C25: =Данные!E14 | D25: =$B$14+$B$13*C25 | E25: =B25-D25 | F25: =E25^2
A26: =Данные!A15 | B26: =Данные!D15 | C26: =Данные!E15 | D26: =$B$14+$B$13*C26 | E26: =B26-D26 | F26: =E26^2
A27: =Данные!A16 | B27: =Данные!D16 | C27: =Данные!E16 | D27: =$B$14+$B$13*C27 | E27: =B27-D27 | F27: =E27^2
A28: =Данные!A17 | B28: =Данные!D17 | C28: =Данные!E17 | D28: =$B$14+$B$13*C28 | E28: =B28-D28 | F28: =E28^2
A29: =Данные!A18 | B29: =Данные!D18 | C29: =Данные!E18 | D29: =$B$14+$B$13*C29 | E29: =B29-D29 | F29: =E29^2
... A34: =Данные!A23 | B34: =Данные!D23 | C34: =Данные!E23 | D34: =$B$14+$B$13*C34 | E34: =B34-D34 | F34: =E34^2
A35: Сумма | E35: =SUM(E18:E34) | F35: =SUM(F18:F34)
A37: Шаг 4. Суммы квадратов и R²
A38: ESS = Σe² | B38: =F35
A39: TSS | B39: =B10
A40: RSS = Σ(δŵ − δw̄)² | B40: =DEVSQ(D18:D34)
A41: R² = RSS/TSS | B41: =B40/B39
A42: R² = 1 − ESS/TSS | B42: =1-B38/B39 | C42: совпадает с предыдущим: в модели есть свободный член
A43: Проверка: RSS + ESS − TSS | B43: =B40+B38-B39 | C43: должно быть 0
A44: Проверка: Σe | B44: =E35 | C44: должно быть 0
A46: Шаг 5. Стандартные ошибки и значимость
A47: n − 2 — степени свободы | B47: =B5-2
A48: s² = ESS/(n − 2) | B48: =B38/B47
A49: s(β̂₂) = √(s² / Σ(z − z̄)²) | B49: =SQRT(B48/B8)
...

Sheet б) Естеств. уровень
A1: б) Естественный уровень безработицы
A2: Это уровень u₀, при котором прогнозный темп роста зарплаты равен нулю: β̂₁ + β̂₂/u₀ = 0, откуда u₀ = −β̂₂/β̂₁.
A4: β̂₁ | B4: ='а) Оценки'!B14
A5: β̂₂ | B5: ='а) Оценки'!B13
A6: u₀ = −β̂₂/β̂₁, % | B6: =-B5/B4
A7: Проверка: β̂₁ + β̂₂/u₀ | B7: =B4+B5/B6 | C7: должно быть 0
A9: Насколько надёжна эта оценка
A10: Наименьшая наблюдаемая u, % | B10: =MIN(Данные!$C$7:$C$23)
A11: Наибольшая наблюдаемая u, % | B11: =MAX(Данные!$C$7:$C$23)
A12: =IF(B6>B11,"u₀ лежит выше всех наблюдаемых значений u — это экстраполяция, к ней нужно относиться осторожно.","u₀ лежит в пределах наблюдаемых значений u.")

Sheet в) Влияние u
A1: в) Когда безработица сильнее всего влияла на темп роста зарплаты
A2: Модель нелинейна по u, поэтому эффект зависит от уровня безработицы: ∂δw/∂u = −β̂₂/u². Чем ниже u, тем эффект сильнее.
A4: β̂₂ | B4: ='а) Оценки'!B13
A6: t | B6: u, % | C6: ∂δw/∂u = −β̂₂/u² | D6: |∂δw/∂u|
A7: =Данные!A7 | B7: =Данные!C7 | C7: =-$B$4/B7^2 | D7: =ABS(C7)
A8: =Данные!A8 | B8: =Данные!C8 | C8: =-$B$4/B8^2 | D8: =ABS(C8)
A9: =Данные!A9 | B9: =Данные!C9 | C9: =-$B$4/B9^2 | D9: =ABS(C9)
A10: =Данные!A10 | B10: =Данные!C10 | C10: =-$B$4/B10^2 | D10: =ABS(C10)
A11: =Данные!A11 | B11: =Данные!C11 | C11: =-$B$4/B11^2 | D11: =ABS(C11)
A12: =Данные!A12 | B12: =Данные!C12 | C12: =-$B$4/B12^2 | D12: =ABS(C12)
A13: =Данные!A13 | B13: =Данные!C13 | C13: =-$B$4/B13^2 | D13: =ABS(C13)
A14: =Данные!A14 | B14: =Данные!C14 | C14: =-$B$4/B14^2 | D14: =ABS(C14)
A15: =Данные!A15 | B15: =Данные!C15 | C15: =-$B$4/B15^2 | D15: =ABS(C15)
A16: =Данные!A16 | B16: =Данные!C16 | C16: =-$B$4/B16^2 | D16: =ABS(C16)
A17: =Данные!A17 | B17: =Данные!C17 | C17: =-$B$4/B17^2 | D17: =ABS(C17)
A18: =Данные!A18 | B18: =Данные!C18 | C18: =-$B$4/B18^2 | D18: =ABS(C18)
... A23: =Данные!A23 | B23: =Данные!C23 | C23: =-$B$4/B23^2 | D23: =ABS(C23)
B25: |∂δw/∂u| | C25: год t | D25: u, %
A26: Наибольшее влияние | B26: =MAX(D7:D23) | C26: =INDEX(A7:A23,MATCH(B26,D7:D23,0)) | D26: =INDEX(B7:B23,MATCH(B26,D7:D23,0))
A27: Наименьшее влияние | B27: =MIN(D7:D23) | C27: =INDEX(A7:A23,MATCH(B27,D7:D23,0)) | D27: =INDEX(B7:B23,MATCH(B27,D7:D23,0))
A29: Год t = 1 в выборку не входит: для него темп роста δw не определён.
A30: Если минимум или максимум u встречается в нескольких годах, ПОИСКПОЗ покажет первый из них.

Sheet г) Интервалы
A1: г) 95-процентные доверительные интервалы для β₁ и β₂
A2: Границы: оценка ± t_кр·s(оценки), где t_кр — двусторонний квантиль распределения Стьюдента с n − 2 степенями свободы.
A4: n − 2 | B4: ='а) Оценки'!B47
A5: Уровень значимости | B5: 0.05 | C5: допущение: 5 %, можно поменять
A6: t_кр | B6: =TINV(B5,B4) | C6: =СТЬЮДРАСПОБР(уровень; n − 2)
A8: Коэффициент | B8: Оценка | C8: s(оценки) | D8: t_кр·s | E8: Нижняя граница | F8: Верхняя граница | G8: Накрывает 0?
A9: β₁ — свободный член | B9: ='а) Оценки'!B14 | C9: ='а) Оценки'!B50 | D9: =$B$6*C9 | E9: =B9-D9 | F9: =B9+D9 | G9: =IF(AND(E9<=0,F9>=0),"да","нет")
A10: β₂ — при 1/u | B10: ='а) Оценки'!B13 | C10: ='а) Оценки'!B49 | D10: =$B$6*C10 | E10: =B10-D10 | F10: =B10+D10 | G10: =IF(AND(E10<=0,F10>=0),"да","нет")
A12: =IF(G9="да","Интервал для β₁ накрывает ноль: свободный член незначим на выбранном уровне.","Интервал для β₁ не накрывает ноль: свободный член значим на выбранном уровне.")
A13: =IF(G10="да","Интервал для β₂ накрывает ноль: коэффициент при 1/u незначим на выбранном уровне.","Интервал для β₂ не накрывает ноль: коэффициент при 1/u значим на выбранном уровне.")
A14: Excel печатает эти же границы в отчёте «Анализ данных → Регрессия», в столбцах «Нижние 95%» и «Верхние 95%».

Sheet Итог
A1: Задача 2.16. Сводка
A3: Пункт | B3: Величина | C3: Значение | D3: P-значение | E3: Вывод
A4: а) | B4: β̂₁ — свободный член | C4: ='а) Оценки'!B14 | D4: ='а) Оценки'!B54 | E4: =IF('а) Оценки'!B54<0.05,"значим","незначим")
A5: а) | B5: β̂₂ — коэффициент при 1/u | C5: ='а) Оценки'!B13 | D5: ='а) Оценки'!B53 | E5: =IF('а) Оценки'!B53<0.05,"значим","незначим")
A6: а) | B6: R² | C6: ='а) Оценки'!B41
A7: а) | B7: F | C7: ='а) Оценки'!B57 | D7: ='а) Оценки'!B58 | E7: =IF('а) Оценки'!B58<0.05,"регрессия значима","регрессия незначима")
A8: б) | B8: u₀ — естественный уровень, % | C8: ='б) Естеств. уровень'!B6 | E8: ='б) Естеств. уровень'!A12
A9: в) | B9: наибольшее |∂δw/∂u| | C9: ='в) Влияние u'!B26 | E9: ="год t = "&'в) Влияние u'!C26
A10: в) | B10: наименьшее |∂δw/∂u| | C10: ='в) Влияние u'!B27 | E10: ="год t = "&'в) Влияние u'!C27
A11: г) | B11: β₁: нижняя граница | C11: ='г) Интервалы'!E9
A12: г) | B12: β₁: верхняя граница | C12: ='г) Интервалы'!F9 | E12: ='г) Интервалы'!A12
A13: г) | B13: β₂: нижняя граница | C13: ='г) Интервалы'!E10
A14: г) | B14: β₂: верхняя граница | C14: ='г) Интервалы'!F10 | E14: ='г) Интервалы'!A13
A16: Что показать на семинаре
A17: 1. Модель линейна по параметрам: регрессор — 1/u, поэтому работают обычные формулы МНК.
A18: 2. Эффект безработицы нелинеен: ∂δw/∂u = −β̂₂/u², он сильнее при низкой безработице.
A19: ="3. В регрессии "&'а) Оценки'!B5&" наблюдений: для первого года темп роста не определён, поэтому степеней свободы n − 2 = "&'а) Оценки'!B47&"."
A20: 4. Значимость можно проверить тремя равносильными способами: по t-статистике, по P-значению и по тому, накрывает ли интервал ноль.
